<?xml version="1.0"?>
<robot name="oscillating_flap" xmlns:xacro="http://ros.org/wiki/xacro">

  <!-- Base: the guard frame -->
  <link name="base_link">
    <inertial>
      <mass value="1.0"/>
      <origin xyz="0 0 0" />
      <inertia ixx="0.01" ixy="0" ixz="0" iyy="0.01" iyz="0" izz="0.01"/>
    </inertial>
    <visual>
      <geometry>
        <cylinder radius="0.4" length="0.05"/>
      </geometry>
      <material name="Blue"/>
    </visual>
    <collision>
      <geometry>
        <cylinder radius="0.4" length="0.05"/>
      </geometry>
    </collision>
  </link>

  <!-- Flapping body -->
  <link name="flap_link">
    <inertial>
      <mass value="0.2"/>
      <origin xyz="0 0 -0.2" />
      <inertia ixx="0.001" ixy="0" ixz="0" iyy="0.001" iyz="0" izz="0.001"/>
    </inertial>
    <visual>
      <geometry>
        <box size="0.1 0.3 0.05"/>
      </geometry>
      <origin xyz="0 0 -0.2" />
      <material name="Red"/>
    </visual>
    <collision>
      <geometry>
        <box size="0.1 0.3 0.05"/>
      </geometry>
      <origin xyz="0 0 -0.2" />
    </collision>
  </link>

  <!-- Spring-damper joint -->
  <joint name="flap_joint" type="revolute">
    <parent link="base_link"/>
    <child link="flap_link"/>
    <origin xyz="0 0 -0.05" rpy="0 0 0"/>
    <axis xyz="0 1 0"/>
    <limit lower="-1.57" upper="1.57" effort="10" velocity="10"/>
    <dynamics damping="0.5" friction="0.0"/>
  </joint>

  <!-- Gazebo-specific spring-damper parameters -->
  <gazebo reference="flap_joint">
    <spring_reference>0.0</spring_reference>
    <spring_stiffness>5.0</spring_stiffness>
    <damping>0.8</damping>
  </gazebo>
  <!-- IMU Link -->
  <link name="imu_link">
    <inertial>
      <mass value="0.001" />
      <origin xyz="0 0 0" rpy="0 0 0" />
      <inertia ixx="1e-6" iyy="1e-6" izz="1e-6" ixy="0" ixz="0" iyz="0" />
    </inertial>
  </link>

  <joint name="imu_joint" type="fixed">
    <parent link="base_link"/>
    <child link="imu_link"/>
    <origin xyz="0 0 0.05" rpy="0 0 0"/>
  </joint>


  <gazebo reference="imu_link">
    <gravity>true</gravity>
    <sensor name="imu_sensor" type="imu">
      <always_on>true</always_on>
      <update_rate>400</update_rate>
      <visualize>true</visualize>
      <topic>__default_topic__</topic>
      <plugin filename="libgazebo_ros_imu_sensor.so" name="imu_plugin">
        <topicName>imu/data</topicName>
        <bodyName>imu_link</bodyName>
        <updateRateHZ>400.0</updateRateHZ>
        <gaussianNoise>0.0</gaussianNoise>
        <xyzOffset>0 0 0</xyzOffset>
        <rpyOffset>0 0 0</rpyOffset>
        <frameName>imu_link</frameName>
        <initialOrientationAsReference>false</initialOrientationAsReference>
      </plugin>
      <pose>0 0 0 0 0 0</pose>
    </sensor>
  </gazebo>


  <!-- Camera Sensor -->
  <gazebo reference="base_link">
    <sensor name="camera_sensor" type="camera">
      <always_on>true</always_on>
      <update_rate>25</update_rate>
      <visualize>true</visualize>
      <camera>
        <horizontal_fov>1.39626</horizontal_fov> <!-- ~80 deg -->
        <image>
          <width>1280</width>
          <height>800</height>
          <format>R8G8B8</format>
        </image>
        <clip>
          <near>0.1</near>
          <far>500</far>
        </clip>
      </camera>
      <plugin name="camera_controller" filename="libgazebo_ros_camera.so">
        <cameraName>front_camera</cameraName>
        <imageTopicName>image_raw</imageTopicName>
        <cameraInfoTopicName>camera_info</cameraInfoTopicName>
        <frameName>base_link</frameName>
      </plugin>
    </sensor>
  </gazebo>
  
</robot>
